{
 "cells": [
  {
   "cell_type": "code",
   "execution_count": 1,
   "id": "3883812c",
   "metadata": {},
   "outputs": [],
   "source": [
    "import numpy as np\n",
    "import matplotlib as plt \n",
    "import tensorflow as tf\n",
    "from tensorflow.keras.models import Sequential\n",
    "from tensorflow.keras.layers import Dense\n",
    "# import the activation functions\n",
    "from tensorflow.keras.losses import MeanSquaredError\n",
    "# loss function for regression models \n",
    "from tensorflow.keras.losses import BinaryCrossentropy\n",
    "# loss function for logistic models\n",
    "from tensorflow.keras.losses import SparseCategoricalCrossentropy\n",
    "\n",
    "import logging\n",
    "logging.getLogger(\"tensorflow\").setLevel(logging.ERROR)\n",
    "\n",
    "tf.random.set_seed(1234)\n",
    "model = Sequential(\n",
    "    [\n",
    "        Dense(units = 1, activation='sigmoid'),\n",
    "    ], name = \"Complex\"\n",
    ")\n",
    "model.compile(\n",
    "    loss = MeanSquaredError(),\n",
    "    optimizer = tf.keras.optimizers.Adam(learning_rate = 0.01)\n",
    ")\n"
   ]
  },
  {
   "cell_type": "code",
   "execution_count": 2,
   "id": "1339d651",
   "metadata": {},
   "outputs": [
    {
     "name": "stdout",
     "output_type": "stream",
     "text": [
      "(200,)\n",
      "(200,)\n",
      "Epoch 1/100\n"
     ]
    },
    {
     "ename": "ValueError",
     "evalue": "in user code:\n\n    File \"C:\\Users\\lhy\\.conda\\envs\\pytorch_test\\lib\\site-packages\\keras\\engine\\training.py\", line 1160, in train_function  *\n        return step_function(self, iterator)\n    File \"C:\\Users\\lhy\\.conda\\envs\\pytorch_test\\lib\\site-packages\\keras\\engine\\training.py\", line 1146, in step_function  **\n        outputs = model.distribute_strategy.run(run_step, args=(data,))\n    File \"C:\\Users\\lhy\\.conda\\envs\\pytorch_test\\lib\\site-packages\\keras\\engine\\training.py\", line 1135, in run_step  **\n        outputs = model.train_step(data)\n    File \"C:\\Users\\lhy\\.conda\\envs\\pytorch_test\\lib\\site-packages\\keras\\engine\\training.py\", line 993, in train_step\n        y_pred = self(x, training=True)\n    File \"C:\\Users\\lhy\\.conda\\envs\\pytorch_test\\lib\\site-packages\\keras\\utils\\traceback_utils.py\", line 70, in error_handler\n        raise e.with_traceback(filtered_tb) from None\n    File \"C:\\Users\\lhy\\.conda\\envs\\pytorch_test\\lib\\site-packages\\keras\\engine\\input_spec.py\", line 250, in assert_input_compatibility\n        raise ValueError(\n\n    ValueError: Exception encountered when calling layer \"Complex\" \"                 f\"(type Sequential).\n    \n    Input 0 of layer \"dense\" is incompatible with the layer: expected min_ndim=2, found ndim=1. Full shape received: (None,)\n    \n    Call arguments received by layer \"Complex\" \"                 f\"(type Sequential):\n      • inputs=tf.Tensor(shape=(None,), dtype=float32)\n      • training=True\n      • mask=None\n",
     "output_type": "error",
     "traceback": [
      "\u001b[1;31m---------------------------------------------------------------------------\u001b[0m",
      "\u001b[1;31mValueError\u001b[0m                                Traceback (most recent call last)",
      "Cell \u001b[1;32mIn[2], line 11\u001b[0m\n\u001b[0;32m      9\u001b[0m \u001b[38;5;28;01mimport\u001b[39;00m \u001b[38;5;21;01mlogging\u001b[39;00m\n\u001b[0;32m     10\u001b[0m logging\u001b[38;5;241m.\u001b[39mgetLogger(\u001b[38;5;124m\"\u001b[39m\u001b[38;5;124mtensorflow\u001b[39m\u001b[38;5;124m\"\u001b[39m)\u001b[38;5;241m.\u001b[39msetLevel(logging\u001b[38;5;241m.\u001b[39mERROR)\n\u001b[1;32m---> 11\u001b[0m \u001b[43mmodel\u001b[49m\u001b[38;5;241;43m.\u001b[39;49m\u001b[43mfit\u001b[49m\u001b[43m(\u001b[49m\n\u001b[0;32m     12\u001b[0m \u001b[43m    \u001b[49m\u001b[43mx\u001b[49m\u001b[43m,\u001b[49m\u001b[43my\u001b[49m\u001b[43m,\u001b[49m\n\u001b[0;32m     13\u001b[0m \u001b[43m    \u001b[49m\u001b[43mepochs\u001b[49m\u001b[43m \u001b[49m\u001b[38;5;241;43m=\u001b[39;49m\u001b[43m \u001b[49m\u001b[38;5;241;43m100\u001b[39;49m\n\u001b[0;32m     14\u001b[0m \u001b[43m)\u001b[49m\n",
      "File \u001b[1;32m~\\.conda\\envs\\pytorch_test\\lib\\site-packages\\keras\\utils\\traceback_utils.py:70\u001b[0m, in \u001b[0;36mfilter_traceback.<locals>.error_handler\u001b[1;34m(*args, **kwargs)\u001b[0m\n\u001b[0;32m     67\u001b[0m     filtered_tb \u001b[38;5;241m=\u001b[39m _process_traceback_frames(e\u001b[38;5;241m.\u001b[39m__traceback__)\n\u001b[0;32m     68\u001b[0m     \u001b[38;5;66;03m# To get the full stack trace, call:\u001b[39;00m\n\u001b[0;32m     69\u001b[0m     \u001b[38;5;66;03m# `tf.debugging.disable_traceback_filtering()`\u001b[39;00m\n\u001b[1;32m---> 70\u001b[0m     \u001b[38;5;28;01mraise\u001b[39;00m e\u001b[38;5;241m.\u001b[39mwith_traceback(filtered_tb) \u001b[38;5;28;01mfrom\u001b[39;00m \u001b[38;5;28;01mNone\u001b[39;00m\n\u001b[0;32m     71\u001b[0m \u001b[38;5;28;01mfinally\u001b[39;00m:\n\u001b[0;32m     72\u001b[0m     \u001b[38;5;28;01mdel\u001b[39;00m filtered_tb\n",
      "File \u001b[1;32m~\\AppData\\Local\\Temp\\__autograph_generated_filenhbil2uq.py:15\u001b[0m, in \u001b[0;36mouter_factory.<locals>.inner_factory.<locals>.tf__train_function\u001b[1;34m(iterator)\u001b[0m\n\u001b[0;32m     13\u001b[0m \u001b[38;5;28;01mtry\u001b[39;00m:\n\u001b[0;32m     14\u001b[0m     do_return \u001b[38;5;241m=\u001b[39m \u001b[38;5;28;01mTrue\u001b[39;00m\n\u001b[1;32m---> 15\u001b[0m     retval_ \u001b[38;5;241m=\u001b[39m ag__\u001b[38;5;241m.\u001b[39mconverted_call(ag__\u001b[38;5;241m.\u001b[39mld(step_function), (ag__\u001b[38;5;241m.\u001b[39mld(\u001b[38;5;28mself\u001b[39m), ag__\u001b[38;5;241m.\u001b[39mld(iterator)), \u001b[38;5;28;01mNone\u001b[39;00m, fscope)\n\u001b[0;32m     16\u001b[0m \u001b[38;5;28;01mexcept\u001b[39;00m:\n\u001b[0;32m     17\u001b[0m     do_return \u001b[38;5;241m=\u001b[39m \u001b[38;5;28;01mFalse\u001b[39;00m\n",
      "\u001b[1;31mValueError\u001b[0m: in user code:\n\n    File \"C:\\Users\\lhy\\.conda\\envs\\pytorch_test\\lib\\site-packages\\keras\\engine\\training.py\", line 1160, in train_function  *\n        return step_function(self, iterator)\n    File \"C:\\Users\\lhy\\.conda\\envs\\pytorch_test\\lib\\site-packages\\keras\\engine\\training.py\", line 1146, in step_function  **\n        outputs = model.distribute_strategy.run(run_step, args=(data,))\n    File \"C:\\Users\\lhy\\.conda\\envs\\pytorch_test\\lib\\site-packages\\keras\\engine\\training.py\", line 1135, in run_step  **\n        outputs = model.train_step(data)\n    File \"C:\\Users\\lhy\\.conda\\envs\\pytorch_test\\lib\\site-packages\\keras\\engine\\training.py\", line 993, in train_step\n        y_pred = self(x, training=True)\n    File \"C:\\Users\\lhy\\.conda\\envs\\pytorch_test\\lib\\site-packages\\keras\\utils\\traceback_utils.py\", line 70, in error_handler\n        raise e.with_traceback(filtered_tb) from None\n    File \"C:\\Users\\lhy\\.conda\\envs\\pytorch_test\\lib\\site-packages\\keras\\engine\\input_spec.py\", line 250, in assert_input_compatibility\n        raise ValueError(\n\n    ValueError: Exception encountered when calling layer \"Complex\" \"                 f\"(type Sequential).\n    \n    Input 0 of layer \"dense\" is incompatible with the layer: expected min_ndim=2, found ndim=1. Full shape received: (None,)\n    \n    Call arguments received by layer \"Complex\" \"                 f\"(type Sequential):\n      • inputs=tf.Tensor(shape=(None,), dtype=float32)\n      • training=True\n      • mask=None\n"
     ]
    }
   ],
   "source": [
    "x1 = np.linspace(0,10,num=100)\n",
    "y1 = np.ones(shape=x1.shape)\n",
    "x2 = np.linspace(50,60,100)\n",
    "y2 = np.zeros(shape=x2.shape)\n",
    "x = np.append(x1,x2)\n",
    "y = np.append(y1,y2)\n",
    "print(x.shape)\n",
    "print(y.shape)\n",
    "import logging\n",
    "logging.getLogger(\"tensorflow\").setLevel(logging.ERROR)\n",
    "model.fit(\n",
    "    x,y,\n",
    "    epochs = 100\n",
    ")\n",
    "\n"
   ]
  },
  {
   "cell_type": "code",
   "execution_count": null,
   "id": "12fecd9e",
   "metadata": {},
   "outputs": [],
   "source": []
  }
 ],
 "metadata": {
  "kernelspec": {
   "display_name": "Python 3 (ipykernel)",
   "language": "python",
   "name": "python3"
  },
  "language_info": {
   "codemirror_mode": {
    "name": "ipython",
    "version": 3
   },
   "file_extension": ".py",
   "mimetype": "text/x-python",
   "name": "python",
   "nbconvert_exporter": "python",
   "pygments_lexer": "ipython3",
   "version": "3.8.18"
  }
 },
 "nbformat": 4,
 "nbformat_minor": 5
}
